<?xml version="1.0" encoding="utf-8"?>
<!-- This URDF was automatically created by SolidWorks to URDF Exporter! Originally created by Stephen Brawner (brawner@gmail.com) 
     Commit Version: 1.5.1-0-g916b5db  Build Version: 1.5.7152.31018
     For more information, please see http://wiki.ros.org/sw_urdf_exporter -->
<robot xmlns:xacro="http://www.ros.org/wiki/xacro"  name="old">
    
    <xacro:property name="body_width" value="0.5" />
    <xacro:property name="body_length" value="1" />
    <xacro:property name="body_height" value="0.09" />
    
    <xacro:property name="l1" value="0.1" />
    <xacro:property name="l2" value="0.5" />
    <xacro:property name="l3" value="0.5" />
    <xacro:property name="l4" value="0.02" />
    <xacro:property name="l_width" value="0.02" />
    <xacro:property name="f_width" value="0.1" />
<!--      -->
    <xacro:property name="l1_pos_x" value="0.4"  />
    <xacro:property name="l1_pos_y" value="0.2"  />
     <xacro:property name="l2_pos_x" value="0"  />
    <xacro:property name="l2_pos_y" value="0.2"  />
     <xacro:property name="l3_pos_x" value="-0.4"  />
    <xacro:property name="l3_pos_y" value="0.2"  />
   <link
    name="body_link">
    <inertial>
      <mass
        value="10" />
      <inertia ixx="1e-3" ixy="0" ixz="0" iyy="1e-3" iyz="0" izz="1e-3" />
    </inertial>
    <visual>
      <geometry>
        <box size="${body_length} ${body_width} ${body_height}"/>
      </geometry>
      <material
        name="">
        <color
          rgba="0.792156862745098 0.819607843137255 0.933333333333333 1" />
      </material>
    </visual>
    <collision>
      <geometry>
        <box size="${body_length} ${body_width} ${body_height}"/>
      </geometry>
    </collision>
  </link>
  
  
  <xacro:macro name="leg" params="name dx dy direction">
     <link
    name="${name}1_link">
    <inertial>
      <mass
        value="1" />
      <inertia ixx="1e-5" ixy="0" ixz="0" iyy="1e-5" iyz="0" izz="1e-5" />
    </inertial>
    <visual>
      <geometry>
        <box size="${l1} ${l_width} ${l_width}"/>
      </geometry>
        <origin xyz="${l1*0.5} 0 0" rpy="0 0 0" />
      <material
        name="">
        <color
          rgba="0.792156862745098 0.819607843137255 0.933333333333333 1" />
      </material>
    </visual>
    <collision>
      <geometry>
         <box size="${l1} ${l_width} ${l_width}"/>
      </geometry>
        <origin xyz="${l1*0.5} 0 0" rpy="0 0 0" />
    </collision>
  </link>
    <joint
    name="${name}1_joint"
    type="continuous">
    <origin
      xyz="${dx} ${dy} ${body_height*0.5 + l_width*0.5}"
      rpy="0 0 ${direction}" />
    <parent
      link="body_link" />
    <child
      link="${name}1_link" />
    <axis
      xyz="0 0 1" />
  </joint>
  
      <link
    name="${name}2_link">
    <inertial>
      <mass
        value="1" />
      <inertia ixx="1e-5" ixy="0" ixz="0" iyy="1e-5" iyz="0" izz="1e-5" />
    </inertial>
    <visual>
      <geometry>
        <box size="${l2} ${l_width} ${l_width}"/>
      </geometry>
        <origin xyz="${l2*0.5} 0 0" rpy="0 0 0" />
      <material
        name="">
        <color
          rgba="0.792156862745098 0.819607843137255 0.933333333333333 1" />
      </material>
    </visual>
    <collision>
      <geometry>
         <box size="${l2} ${l_width} ${l_width}"/>
      </geometry>
        <origin xyz="0 0 0" rpy="0 0 0" />
    </collision>
  </link>
    <joint
    name="${name}2_joint"
    type="continuous">
    <origin
      xyz="${l1+l_width*0.5} 0 0"
      rpy="0 0 0" />
    <parent
      link="${name}1_link" />
    <child
      link="${name}2_link" />
    <axis
      xyz="0 1 0" />
  </joint>
  
        <link
    name="${name}3_link">
    <inertial>
      <mass
        value="1" />
      <inertia ixx="1e-5" ixy="0" ixz="0" iyy="1e-5" iyz="0" izz="1e-5" />
    </inertial>
    <visual>
      <geometry>
        <box size="${l3} ${l_width} ${l_width}"/>
      </geometry>
        <origin xyz="${l3*0.5} 0 0" rpy="0 0 0" />
      <material
        name="">
        <color
          rgba="0.792156862745098 0.819607843137255 0.933333333333333 1" />
      </material>
    </visual>
    <collision>
      <geometry>
         <box size="${l3} ${l_width} ${l_width}"/>
      </geometry>
        <origin xyz="0 0 0" rpy="0 0 0" />
    </collision>
  </link>
    <joint
    name="${name}3_joint"
    type="continuous">
    <origin
      xyz="${l2+l_width*0.5} 0 0"
      rpy="0 0 0" />
    <parent
      link="${name}2_link" />
    <child
      link="${name}3_link" />
    <axis
      xyz="0 1 0" />
  </joint>
  
  <link
    name="${name}4_link">
    <inertial>
      <mass
        value="1" />
      <inertia ixx="1e-5" ixy="0" ixz="0" iyy="1e-5" iyz="0" izz="1e-5" />
    </inertial>
    <visual>
      <geometry>
         <box size="${l4} ${f_width} ${l_width}"/>
      </geometry>
        <origin xyz="${l4*0.5} 0 0" rpy="0 0 0" />
      <material
        name="">
        <color
          rgba="0.792156862745098 0.819607843137255 0.933333333333333 1" />
      </material>
    </visual>
    <collision>
      <geometry>
         <box size="${l4} ${f_width} ${l_width}"/>
      </geometry>
        <origin xyz="0 0 0" rpy="0 0 0" />
    </collision>
  </link>
    <joint
    name="${name}4_joint"
    type="continuous">
    <origin
      xyz="${l3+l_width*0.5} 0 0"
      rpy="0 0 0" />
    <parent
      link="${name}3_link" />
    <child
      link="${name}4_link" />
    <axis
      xyz="0 1 0" />
  </joint>
  
  </xacro:macro>
  
    <xacro:leg name="left_forward" dx="${l1_pos_x}" dy="${l1_pos_y}" direction="${pi/2}" />
    <xacro:leg name="right_forward" dx="${l1_pos_x}" dy="${-l1_pos_y}" direction="${-pi/2}"/>
    <xacro:leg name="left_middle" dx="${l2_pos_x}" dy="${l2_pos_y}" direction="${pi/2}" />
    <xacro:leg name="right_middle" dx="${l2_pos_x}" dy="${-l2_pos_y}" direction="${-pi/2}"/>
    <xacro:leg name="left_backward" dx="${l3_pos_x}" dy="${l3_pos_y}" direction="${pi/2}" />
    <xacro:leg name="right_backward" dx="${l3_pos_x}" dy="${-l3_pos_y}" direction="${-pi/2}"/>
</robot>
